[2021-06-11 18:34:10,624] {taskinstance.py:876} INFO - Dependencies all met for <TaskInstance: postgres_operator_dag.populate_pet_table 2021-06-11T18:34:07.870474+00:00 [queued]>
[2021-06-11 18:34:10,643] {taskinstance.py:876} INFO - Dependencies all met for <TaskInstance: postgres_operator_dag.populate_pet_table 2021-06-11T18:34:07.870474+00:00 [queued]>
[2021-06-11 18:34:10,643] {taskinstance.py:1067} INFO - 
--------------------------------------------------------------------------------
[2021-06-11 18:34:10,644] {taskinstance.py:1068} INFO - Starting attempt 1 of 1
[2021-06-11 18:34:10,646] {taskinstance.py:1069} INFO - 
--------------------------------------------------------------------------------
[2021-06-11 18:34:10,655] {taskinstance.py:1087} INFO - Executing <Task(PostgresOperator): populate_pet_table> on 2021-06-11T18:34:07.870474+00:00
[2021-06-11 18:34:10,663] {standard_task_runner.py:52} INFO - Started process 5141 to run task
[2021-06-11 18:34:10,668] {standard_task_runner.py:76} INFO - Running: ['***', 'tasks', 'run', 'postgres_operator_dag', 'populate_pet_table', '2021-06-11T18:34:07.870474+00:00', '--job-id', '14', '--pool', 'default_pool', '--raw', '--subdir', 'DAGS_FOLDER/example_postgres.py', '--cfg-path', '/tmp/tmpca9tillo', '--error-file', '/tmp/tmp308clilm']
[2021-06-11 18:34:10,669] {standard_task_runner.py:77} INFO - Job 14: Subtask populate_pet_table
[2021-06-11 18:34:10,713] {logging_mixin.py:104} INFO - Running <TaskInstance: postgres_operator_dag.populate_pet_table 2021-06-11T18:34:07.870474+00:00 [running]> on host cd242b243f35
[2021-06-11 18:34:10,766] {taskinstance.py:1282} INFO - Exporting the following env vars:
AIRFLOW_CTX_DAG_OWNER=***
AIRFLOW_CTX_DAG_ID=postgres_operator_dag
AIRFLOW_CTX_TASK_ID=populate_pet_table
AIRFLOW_CTX_EXECUTION_DATE=2021-06-11T18:34:07.870474+00:00
AIRFLOW_CTX_DAG_RUN_ID=manual__2021-06-11T18:34:07.870474+00:00
[2021-06-11 18:34:10,767] {postgres.py:70} INFO - Executing: 
            INSERT INTO pet VALUES ( 1,'Max', 'Dog', '2018-07-05', 'Jane');
            INSERT INTO pet VALUES ( 2,'Susie', 'Cat', '2019-05-01', 'Phil');
            INSERT INTO pet VALUES ( 3,'Lester', 'Hamster', '2020-06-23', 'Lily');
            INSERT INTO pet VALUES ( 4,'Quincy', 'Parrot', '2013-08-11', 'Anne');
            
[2021-06-11 18:34:10,777] {base.py:78} INFO - Using connection to: id: docker-postgres. Host: 192.168.1.27, Port: 5432, Schema: , Login: postgres, Password: ***, extra: {}
[2021-06-11 18:34:10,790] {dbapi.py:204} INFO - Running statement: 
            INSERT INTO pet VALUES ( 1,'Max', 'Dog', '2018-07-05', 'Jane');
            INSERT INTO pet VALUES ( 2,'Susie', 'Cat', '2019-05-01', 'Phil');
            INSERT INTO pet VALUES ( 3,'Lester', 'Hamster', '2020-06-23', 'Lily');
            INSERT INTO pet VALUES ( 4,'Quincy', 'Parrot', '2013-08-11', 'Anne');
            , parameters: None
[2021-06-11 18:34:10,802] {taskinstance.py:1481} ERROR - Task failed with exception
Traceback (most recent call last):
  File "/home/airflow/.local/lib/python3.6/site-packages/airflow/models/taskinstance.py", line 1137, in _run_raw_task
    self._prepare_and_execute_task_with_callbacks(context, task)
  File "/home/airflow/.local/lib/python3.6/site-packages/airflow/models/taskinstance.py", line 1311, in _prepare_and_execute_task_with_callbacks
    result = self._execute_task(context, task_copy)
  File "/home/airflow/.local/lib/python3.6/site-packages/airflow/models/taskinstance.py", line 1341, in _execute_task
    result = task_copy.execute(context=context)
  File "/home/airflow/.local/lib/python3.6/site-packages/airflow/providers/postgres/operators/postgres.py", line 72, in execute
    self.hook.run(self.sql, self.autocommit, parameters=self.parameters)
  File "/home/airflow/.local/lib/python3.6/site-packages/airflow/hooks/dbapi.py", line 184, in run
    self._run_command(cur, sql_statement, parameters)
  File "/home/airflow/.local/lib/python3.6/site-packages/airflow/hooks/dbapi.py", line 208, in _run_command
    cur.execute(sql_statement)
psycopg2.errors.UniqueViolation: duplicate key value violates unique constraint "pet_pkey"
DETAIL:  Key (pet_id)=(1) already exists.

[2021-06-11 18:34:10,807] {taskinstance.py:1531} INFO - Marking task as FAILED. dag_id=postgres_operator_dag, task_id=populate_pet_table, execution_date=20210611T183407, start_date=20210611T183410, end_date=20210611T183410
[2021-06-11 18:34:10,839] {local_task_job.py:151} INFO - Task exited with return code 1
