[2021-06-27 07:14:15,796] {taskinstance.py:876} INFO - Dependencies all met for <TaskInstance: postgretomysql.create_postgresql_schema 2021-06-27T07:14:14.356280+00:00 [queued]>
[2021-06-27 07:14:15,820] {taskinstance.py:876} INFO - Dependencies all met for <TaskInstance: postgretomysql.create_postgresql_schema 2021-06-27T07:14:14.356280+00:00 [queued]>
[2021-06-27 07:14:15,822] {taskinstance.py:1067} INFO - 
--------------------------------------------------------------------------------
[2021-06-27 07:14:15,822] {taskinstance.py:1068} INFO - Starting attempt 1 of 2
[2021-06-27 07:14:15,826] {taskinstance.py:1069} INFO - 
--------------------------------------------------------------------------------
[2021-06-27 07:14:15,838] {taskinstance.py:1087} INFO - Executing <Task(PostgresOperator): create_postgresql_schema> on 2021-06-27T07:14:14.356280+00:00
[2021-06-27 07:14:15,850] {standard_task_runner.py:52} INFO - Started process 4994 to run task
[2021-06-27 07:14:15,856] {standard_task_runner.py:76} INFO - Running: ['***', 'tasks', 'run', 'postgretomysql', 'create_postgresql_schema', '2021-06-27T07:14:14.356280+00:00', '--job-id', '39', '--pool', 'default_pool', '--raw', '--subdir', 'DAGS_FOLDER/postgresql-collect.py', '--cfg-path', '/tmp/tmptfx7hw2c', '--error-file', '/tmp/tmp9ql4c8d6']
[2021-06-27 07:14:15,858] {standard_task_runner.py:77} INFO - Job 39: Subtask create_postgresql_schema
[2021-06-27 07:14:15,917] {logging_mixin.py:104} INFO - Running <TaskInstance: postgretomysql.create_postgresql_schema 2021-06-27T07:14:14.356280+00:00 [running]> on host b69deda3a989
[2021-06-27 07:14:15,994] {taskinstance.py:1282} INFO - Exporting the following env vars:
AIRFLOW_CTX_DAG_EMAIL=tech@innospark.com
AIRFLOW_CTX_DAG_OWNER=***
AIRFLOW_CTX_DAG_ID=postgretomysql
AIRFLOW_CTX_TASK_ID=create_postgresql_schema
AIRFLOW_CTX_EXECUTION_DATE=2021-06-27T07:14:14.356280+00:00
AIRFLOW_CTX_DAG_RUN_ID=manual__2021-06-27T07:14:14.356280+00:00
[2021-06-27 07:14:15,995] {postgres.py:70} INFO - Executing: -- Drop tables

DROP TABLE test.invoice;

DROP TABLE test.customer;

-- test.customer definition

CREATE TABLE IF NOT EXISTS test.customer (
	id int4 NOT NULL,
	customername varchar NULL,
	address varchar NULL,
	country varchar NULL,
	phone varchar NULL,
	CONSTRAINT customer_pk PRIMARY KEY (id)
);

-- test.invoice definition

CREATE TABLE IF NOT EXISTS test.invoice (
	id int4 NOT NULL,
	idcustomer int4 NULL,
	orderdate date NULL,
	subtotal float4 NULL,
	discount float4 NULL,
	region varchar NULL,
	salesperson varchar NULL,
	CONSTRAINT invoice_pk PRIMARY KEY (id),
	CONSTRAINT customer_fk FOREIGN KEY (id) REFERENCES test.customer(id)
);
[2021-06-27 07:14:16,010] {base.py:78} INFO - Using connection to: id: docker-postgres. Host: 192.168.1.27, Port: 5432, Schema: , Login: postgres, Password: ***, extra: {}
[2021-06-27 07:14:16,028] {dbapi.py:204} INFO - Running statement: -- Drop tables

DROP TABLE test.invoice;

DROP TABLE test.customer;

-- test.customer definition

CREATE TABLE IF NOT EXISTS test.customer (
	id int4 NOT NULL,
	customername varchar NULL,
	address varchar NULL,
	country varchar NULL,
	phone varchar NULL,
	CONSTRAINT customer_pk PRIMARY KEY (id)
);

-- test.invoice definition

CREATE TABLE IF NOT EXISTS test.invoice (
	id int4 NOT NULL,
	idcustomer int4 NULL,
	orderdate date NULL,
	subtotal float4 NULL,
	discount float4 NULL,
	region varchar NULL,
	salesperson varchar NULL,
	CONSTRAINT invoice_pk PRIMARY KEY (id),
	CONSTRAINT customer_fk FOREIGN KEY (id) REFERENCES test.customer(id)
);, parameters: None
[2021-06-27 07:14:16,036] {taskinstance.py:1481} ERROR - Task failed with exception
Traceback (most recent call last):
  File "/home/airflow/.local/lib/python3.6/site-packages/airflow/models/taskinstance.py", line 1137, in _run_raw_task
    self._prepare_and_execute_task_with_callbacks(context, task)
  File "/home/airflow/.local/lib/python3.6/site-packages/airflow/models/taskinstance.py", line 1311, in _prepare_and_execute_task_with_callbacks
    result = self._execute_task(context, task_copy)
  File "/home/airflow/.local/lib/python3.6/site-packages/airflow/models/taskinstance.py", line 1341, in _execute_task
    result = task_copy.execute(context=context)
  File "/home/airflow/.local/lib/python3.6/site-packages/airflow/providers/postgres/operators/postgres.py", line 72, in execute
    self.hook.run(self.sql, self.autocommit, parameters=self.parameters)
  File "/home/airflow/.local/lib/python3.6/site-packages/airflow/hooks/dbapi.py", line 184, in run
    self._run_command(cur, sql_statement, parameters)
  File "/home/airflow/.local/lib/python3.6/site-packages/airflow/hooks/dbapi.py", line 208, in _run_command
    cur.execute(sql_statement)
psycopg2.errors.UndefinedTable: table "invoice" does not exist

[2021-06-27 07:14:16,040] {taskinstance.py:1531} INFO - Marking task as UP_FOR_RETRY. dag_id=postgretomysql, task_id=create_postgresql_schema, execution_date=20210627T071414, start_date=20210627T071415, end_date=20210627T071416
[2021-06-27 07:14:16,107] {local_task_job.py:151} INFO - Task exited with return code 1
