[2021-06-27 20:32:51,039] {taskinstance.py:876} INFO - Dependencies all met for <TaskInstance: mysqltomongo.import_mysql_customer 2021-06-27T20:31:36.477408+00:00 [queued]>
[2021-06-27 20:32:51,099] {taskinstance.py:876} INFO - Dependencies all met for <TaskInstance: mysqltomongo.import_mysql_customer 2021-06-27T20:31:36.477408+00:00 [queued]>
[2021-06-27 20:32:51,104] {taskinstance.py:1067} INFO - 
--------------------------------------------------------------------------------
[2021-06-27 20:32:51,106] {taskinstance.py:1068} INFO - Starting attempt 1 of 2
[2021-06-27 20:32:51,118] {taskinstance.py:1069} INFO - 
--------------------------------------------------------------------------------
[2021-06-27 20:32:51,185] {taskinstance.py:1087} INFO - Executing <Task(PythonOperator): import_mysql_customer> on 2021-06-27T20:31:36.477408+00:00
[2021-06-27 20:32:51,239] {standard_task_runner.py:76} INFO - Running: ['***', 'tasks', 'run', 'mysqltomongo', 'import_mysql_customer', '2021-06-27T20:31:36.477408+00:00', '--job-id', '129', '--pool', 'default_pool', '--raw', '--subdir', 'DAGS_FOLDER/sqlMongo.py', '--cfg-path', '/tmp/tmpvlcac207', '--error-file', '/tmp/tmp10didcfg']
[2021-06-27 20:32:51,242] {standard_task_runner.py:77} INFO - Job 129: Subtask import_mysql_customer
[2021-06-27 20:32:51,223] {standard_task_runner.py:52} INFO - Started process 3214 to run task
[2021-06-27 20:32:51,436] {logging_mixin.py:104} INFO - Running <TaskInstance: mysqltomongo.import_mysql_customer 2021-06-27T20:31:36.477408+00:00 [running]> on host b69deda3a989
[2021-06-27 20:32:51,624] {taskinstance.py:1282} INFO - Exporting the following env vars:
AIRFLOW_CTX_DAG_EMAIL=tech@innospark.com
AIRFLOW_CTX_DAG_OWNER=***
AIRFLOW_CTX_DAG_ID=mysqltomongo
AIRFLOW_CTX_TASK_ID=import_mysql_customer
AIRFLOW_CTX_EXECUTION_DATE=2021-06-27T20:31:36.477408+00:00
AIRFLOW_CTX_DAG_RUN_ID=manual__2021-06-27T20:31:36.477408+00:00
[2021-06-27 20:32:51,630] {taskinstance.py:1481} ERROR - Task failed with exception
Traceback (most recent call last):
  File "/home/airflow/.local/lib/python3.6/site-packages/airflow/models/taskinstance.py", line 1137, in _run_raw_task
    self._prepare_and_execute_task_with_callbacks(context, task)
  File "/home/airflow/.local/lib/python3.6/site-packages/airflow/models/taskinstance.py", line 1311, in _prepare_and_execute_task_with_callbacks
    result = self._execute_task(context, task_copy)
  File "/home/airflow/.local/lib/python3.6/site-packages/airflow/models/taskinstance.py", line 1341, in _execute_task
    result = task_copy.execute(context=context)
  File "/home/airflow/.local/lib/python3.6/site-packages/airflow/operators/python.py", line 150, in execute
    return_value = self.execute_callable()
  File "/home/airflow/.local/lib/python3.6/site-packages/airflow/operators/python.py", line 161, in execute_callable
    return self.python_callable(*self.op_args, **self.op_kwargs)
  File "/opt/airflow/dags/sqlMongo.py", line 26, in mysql_bulk_load_mongo
    conn = MongoHook(mysql_conn_id=kwargs['conn_id'])
NameError: name 'MongoHook' is not defined
[2021-06-27 20:32:51,638] {taskinstance.py:1531} INFO - Marking task as UP_FOR_RETRY. dag_id=mysqltomongo, task_id=import_mysql_customer, execution_date=20210627T203136, start_date=20210627T203251, end_date=20210627T203251
[2021-06-27 20:32:51,732] {local_task_job.py:151} INFO - Task exited with return code 1
