[2021-06-27 17:50:14,992] {taskinstance.py:876} INFO - Dependencies all met for <TaskInstance: postgretomysql.create_postgresql_schema 2021-06-27T17:48:49.799682+00:00 [queued]>
[2021-06-27 17:50:15,010] {taskinstance.py:876} INFO - Dependencies all met for <TaskInstance: postgretomysql.create_postgresql_schema 2021-06-27T17:48:49.799682+00:00 [queued]>
[2021-06-27 17:50:15,011] {taskinstance.py:1067} INFO - 
--------------------------------------------------------------------------------
[2021-06-27 17:50:15,012] {taskinstance.py:1068} INFO - Starting attempt 2 of 2
[2021-06-27 17:50:15,016] {taskinstance.py:1069} INFO - 
--------------------------------------------------------------------------------
[2021-06-27 17:50:15,035] {taskinstance.py:1087} INFO - Executing <Task(PostgresOperator): create_postgresql_schema> on 2021-06-27T17:48:49.799682+00:00
[2021-06-27 17:50:15,046] {standard_task_runner.py:52} INFO - Started process 6436 to run task
[2021-06-27 17:50:15,052] {standard_task_runner.py:76} INFO - Running: ['***', 'tasks', 'run', 'postgretomysql', 'create_postgresql_schema', '2021-06-27T17:48:49.799682+00:00', '--job-id', '77', '--pool', 'default_pool', '--raw', '--subdir', 'DAGS_FOLDER/postgresql-collect.py', '--cfg-path', '/tmp/tmpg7fn68rr', '--error-file', '/tmp/tmpxdv9sr_u']
[2021-06-27 17:50:15,053] {standard_task_runner.py:77} INFO - Job 77: Subtask create_postgresql_schema
[2021-06-27 17:50:15,115] {logging_mixin.py:104} INFO - Running <TaskInstance: postgretomysql.create_postgresql_schema 2021-06-27T17:48:49.799682+00:00 [running]> on host b69deda3a989
[2021-06-27 17:50:15,184] {taskinstance.py:1282} INFO - Exporting the following env vars:
AIRFLOW_CTX_DAG_EMAIL=tech@innospark.com
AIRFLOW_CTX_DAG_OWNER=***
AIRFLOW_CTX_DAG_ID=postgretomysql
AIRFLOW_CTX_TASK_ID=create_postgresql_schema
AIRFLOW_CTX_EXECUTION_DATE=2021-06-27T17:48:49.799682+00:00
AIRFLOW_CTX_DAG_RUN_ID=manual__2021-06-27T17:48:49.799682+00:00
[2021-06-27 17:50:15,185] {postgres.py:70} INFO - Executing: -- Drop tables

DROP TABLE IF EXISTS test.invoice;

DROP TABLE IF EXISTS test.customer;

-- test.customer definition

CREATE TABLE IF NOT EXISTS test.customer (
	id int4 NOT NULL,
	customername varchar NULL,
	address varchar NULL,
	country varchar NULL,
	phone varchar NULL,
	CONSTRAINT customer_pk PRIMARY KEY (id)
);

-- test.invoice definition

CREATE TABLE IF NOT EXISTS test.invoice (
	id int4 NOT NULL,
	idcustomer int4 NULL,
	orderdate date NULL,
	subtotal float4 NULL,
	discount float4 NULL,
	region varchar NULL,
	salesperson varchar NULL,
	CONSTRAINT invoice_pk PRIMARY KEY (id),
	CONSTRAINT customer_fk FOREIGN KEY (id) REFERENCES test.customer(id)
);
[2021-06-27 17:50:15,198] {base.py:78} INFO - Using connection to: id: docker-postgres. Host: 192.168.1.27, Port: 5432, Schema: , Login: postgres, Password: ***, extra: {}
[2021-06-27 17:50:36,237] {taskinstance.py:1481} ERROR - Task failed with exception
Traceback (most recent call last):
  File "/home/airflow/.local/lib/python3.6/site-packages/airflow/models/taskinstance.py", line 1137, in _run_raw_task
    self._prepare_and_execute_task_with_callbacks(context, task)
  File "/home/airflow/.local/lib/python3.6/site-packages/airflow/models/taskinstance.py", line 1311, in _prepare_and_execute_task_with_callbacks
    result = self._execute_task(context, task_copy)
  File "/home/airflow/.local/lib/python3.6/site-packages/airflow/models/taskinstance.py", line 1341, in _execute_task
    result = task_copy.execute(context=context)
  File "/home/airflow/.local/lib/python3.6/site-packages/airflow/providers/postgres/operators/postgres.py", line 72, in execute
    self.hook.run(self.sql, self.autocommit, parameters=self.parameters)
  File "/home/airflow/.local/lib/python3.6/site-packages/airflow/hooks/dbapi.py", line 177, in run
    with closing(self.get_conn()) as conn:
  File "/home/airflow/.local/lib/python3.6/site-packages/airflow/providers/postgres/hooks/postgres.py", line 113, in get_conn
    self.conn = psycopg2.connect(**conn_args)
  File "/home/airflow/.local/lib/python3.6/site-packages/psycopg2/__init__.py", line 127, in connect
    conn = _connect(dsn, connection_factory=connection_factory, **kwasync)
psycopg2.OperationalError: could not connect to server: Connection refused
	Is the server running on host "192.168.1.27" and accepting
	TCP/IP connections on port 5432?

[2021-06-27 17:50:36,240] {taskinstance.py:1531} INFO - Marking task as FAILED. dag_id=postgretomysql, task_id=create_postgresql_schema, execution_date=20210627T174849, start_date=20210627T175014, end_date=20210627T175036
[2021-06-27 17:50:36,323] {local_task_job.py:151} INFO - Task exited with return code 1
