[2021-06-27 17:18:27,032] {taskinstance.py:876} INFO - Dependencies all met for <TaskInstance: example_mongo.import_mysql_customer 2021-06-27T17:18:25.915506+00:00 [queued]>
[2021-06-27 17:18:27,044] {taskinstance.py:876} INFO - Dependencies all met for <TaskInstance: example_mongo.import_mysql_customer 2021-06-27T17:18:25.915506+00:00 [queued]>
[2021-06-27 17:18:27,045] {taskinstance.py:1067} INFO - 
--------------------------------------------------------------------------------
[2021-06-27 17:18:27,046] {taskinstance.py:1068} INFO - Starting attempt 1 of 1
[2021-06-27 17:18:27,061] {taskinstance.py:1069} INFO - 
--------------------------------------------------------------------------------
[2021-06-27 17:18:27,078] {taskinstance.py:1087} INFO - Executing <Task(PythonOperator): import_mysql_customer> on 2021-06-27T17:18:25.915506+00:00
[2021-06-27 17:18:27,085] {standard_task_runner.py:52} INFO - Started process 4743 to run task
[2021-06-27 17:18:27,090] {standard_task_runner.py:76} INFO - Running: ['***', 'tasks', 'run', 'example_mongo', 'import_mysql_customer', '2021-06-27T17:18:25.915506+00:00', '--job-id', '72', '--pool', 'default_pool', '--raw', '--subdir', 'DAGS_FOLDER/example_mongo.py', '--cfg-path', '/tmp/tmpkkvyi0x7', '--error-file', '/tmp/tmpl_3n73g_']
[2021-06-27 17:18:27,092] {standard_task_runner.py:77} INFO - Job 72: Subtask import_mysql_customer
[2021-06-27 17:18:27,142] {logging_mixin.py:104} INFO - Running <TaskInstance: example_mongo.import_mysql_customer 2021-06-27T17:18:25.915506+00:00 [running]> on host b69deda3a989
[2021-06-27 17:18:27,201] {taskinstance.py:1282} INFO - Exporting the following env vars:
AIRFLOW_CTX_DAG_OWNER=***
AIRFLOW_CTX_DAG_ID=example_mongo
AIRFLOW_CTX_TASK_ID=import_mysql_customer
AIRFLOW_CTX_EXECUTION_DATE=2021-06-27T17:18:25.915506+00:00
AIRFLOW_CTX_DAG_RUN_ID=manual__2021-06-27T17:18:25.915506+00:00
[2021-06-27 17:18:27,212] {base.py:78} INFO - Using connection to: id: docker-mongo. Host: 192.168.1.27, Port: 27017, Schema: , Login: Admin, Password: None, extra: {}
[2021-06-27 17:18:57,264] {taskinstance.py:1481} ERROR - Task failed with exception
Traceback (most recent call last):
  File "/home/airflow/.local/lib/python3.6/site-packages/airflow/models/taskinstance.py", line 1137, in _run_raw_task
    self._prepare_and_execute_task_with_callbacks(context, task)
  File "/home/airflow/.local/lib/python3.6/site-packages/airflow/models/taskinstance.py", line 1311, in _prepare_and_execute_task_with_callbacks
    result = self._execute_task(context, task_copy)
  File "/home/airflow/.local/lib/python3.6/site-packages/airflow/models/taskinstance.py", line 1341, in _execute_task
    result = task_copy.execute(context=context)
  File "/home/airflow/.local/lib/python3.6/site-packages/airflow/operators/python.py", line 150, in execute
    return_value = self.execute_callable()
  File "/home/airflow/.local/lib/python3.6/site-packages/airflow/operators/python.py", line 161, in execute_callable
    return self.python_callable(*self.op_args, **self.op_kwargs)
  File "/opt/airflow/dags/example_mongo.py", line 15, in mysql_bulk_load_mongo
    conn.insert_one(mongo_collection = kwargs['table_name'], doc=data, mongo_db='test')
  File "/home/airflow/.local/lib/python3.6/site-packages/airflow/providers/mongo/hooks/mongo.py", line 160, in insert_one
    return collection.insert_one(doc, **kwargs)
  File "/home/airflow/.local/lib/python3.6/site-packages/pymongo/collection.py", line 701, in insert_one
    session=session),
  File "/home/airflow/.local/lib/python3.6/site-packages/pymongo/collection.py", line 615, in _insert
    bypass_doc_val, session)
  File "/home/airflow/.local/lib/python3.6/site-packages/pymongo/collection.py", line 603, in _insert_one
    acknowledged, _insert_command, session)
  File "/home/airflow/.local/lib/python3.6/site-packages/pymongo/mongo_client.py", line 1497, in _retryable_write
    with self._tmp_session(session) as s:
  File "/usr/local/lib/python3.6/contextlib.py", line 81, in __enter__
    return next(self.gen)
  File "/home/airflow/.local/lib/python3.6/site-packages/pymongo/mongo_client.py", line 1829, in _tmp_session
    s = self._ensure_session(session)
  File "/home/airflow/.local/lib/python3.6/site-packages/pymongo/mongo_client.py", line 1816, in _ensure_session
    return self.__start_session(True, causal_consistency=False)
  File "/home/airflow/.local/lib/python3.6/site-packages/pymongo/mongo_client.py", line 1766, in __start_session
    server_session = self._get_server_session()
  File "/home/airflow/.local/lib/python3.6/site-packages/pymongo/mongo_client.py", line 1802, in _get_server_session
    return self._topology.get_server_session()
  File "/home/airflow/.local/lib/python3.6/site-packages/pymongo/topology.py", line 499, in get_server_session
    None)
  File "/home/airflow/.local/lib/python3.6/site-packages/pymongo/topology.py", line 217, in _select_servers_loop
    (self._error_message(selector), timeout, self.description))
pymongo.errors.ServerSelectionTimeoutError: 192.168.1.27:27017: timed out, Timeout: 30s, Topology Description: <TopologyDescription id: 60d8b2e313a584291c7ff91e, topology_type: Single, servers: [<ServerDescription ('192.168.1.27', 27017) server_type: Unknown, rtt: None, error=NetworkTimeout('192.168.1.27:27017: timed out',)>]>
[2021-06-27 17:18:57,266] {taskinstance.py:1531} INFO - Marking task as FAILED. dag_id=example_mongo, task_id=import_mysql_customer, execution_date=20210627T171825, start_date=20210627T171827, end_date=20210627T171857
[2021-06-27 17:18:57,316] {local_task_job.py:151} INFO - Task exited with return code 1
