[2021-06-27 17:31:57,692] {taskinstance.py:876} INFO - Dependencies all met for <TaskInstance: example_mongo.import_mysql_customer 2021-06-27T17:31:56.128094+00:00 [queued]>
[2021-06-27 17:31:57,728] {taskinstance.py:876} INFO - Dependencies all met for <TaskInstance: example_mongo.import_mysql_customer 2021-06-27T17:31:56.128094+00:00 [queued]>
[2021-06-27 17:31:57,730] {taskinstance.py:1067} INFO - 
--------------------------------------------------------------------------------
[2021-06-27 17:31:57,731] {taskinstance.py:1068} INFO - Starting attempt 1 of 1
[2021-06-27 17:31:57,738] {taskinstance.py:1069} INFO - 
--------------------------------------------------------------------------------
[2021-06-27 17:31:57,761] {taskinstance.py:1087} INFO - Executing <Task(PythonOperator): import_mysql_customer> on 2021-06-27T17:31:56.128094+00:00
[2021-06-27 17:31:57,770] {standard_task_runner.py:52} INFO - Started process 5456 to run task
[2021-06-27 17:31:57,780] {standard_task_runner.py:76} INFO - Running: ['***', 'tasks', 'run', 'example_mongo', 'import_mysql_customer', '2021-06-27T17:31:56.128094+00:00', '--job-id', '74', '--pool', 'default_pool', '--raw', '--subdir', 'DAGS_FOLDER/example_mongo.py', '--cfg-path', '/tmp/tmpvv0a1byb', '--error-file', '/tmp/tmp0clr_2js']
[2021-06-27 17:31:57,782] {standard_task_runner.py:77} INFO - Job 74: Subtask import_mysql_customer
[2021-06-27 17:31:57,850] {logging_mixin.py:104} INFO - Running <TaskInstance: example_mongo.import_mysql_customer 2021-06-27T17:31:56.128094+00:00 [running]> on host b69deda3a989
[2021-06-27 17:31:57,939] {taskinstance.py:1282} INFO - Exporting the following env vars:
AIRFLOW_CTX_DAG_OWNER=***
AIRFLOW_CTX_DAG_ID=example_mongo
AIRFLOW_CTX_TASK_ID=import_mysql_customer
AIRFLOW_CTX_EXECUTION_DATE=2021-06-27T17:31:56.128094+00:00
AIRFLOW_CTX_DAG_RUN_ID=manual__2021-06-27T17:31:56.128094+00:00
[2021-06-27 17:31:57,953] {connection.py:360} ERROR - Failed parsing the json for conn_id docker-mongo
Traceback (most recent call last):
  File "/home/airflow/.local/lib/python3.6/site-packages/airflow/models/connection.py", line 357, in extra_dejson
    obj = json.loads(self.extra)
  File "/usr/local/lib/python3.6/json/__init__.py", line 354, in loads
    return _default_decoder.decode(s)
  File "/usr/local/lib/python3.6/json/decoder.py", line 339, in decode
    obj, end = self.raw_decode(s, idx=_w(s, 0).end())
  File "/usr/local/lib/python3.6/json/decoder.py", line 357, in raw_decode
    raise JSONDecodeError("Expecting value", s, err.value) from None
json.decoder.JSONDecodeError: Expecting value: line 1 column 1 (char 0)
[2021-06-27 17:31:57,956] {base.py:78} INFO - Using connection to: id: docker-mongo. Host: localhost, Port: 27017, Schema: test, Login: , Password: None, extra: {}
[2021-06-27 17:31:57,957] {connection.py:360} ERROR - Failed parsing the json for conn_id docker-mongo
Traceback (most recent call last):
  File "/home/airflow/.local/lib/python3.6/site-packages/airflow/models/connection.py", line 357, in extra_dejson
    obj = json.loads(self.extra)
  File "/usr/local/lib/python3.6/json/__init__.py", line 354, in loads
    return _default_decoder.decode(s)
  File "/usr/local/lib/python3.6/json/decoder.py", line 339, in decode
    obj, end = self.raw_decode(s, idx=_w(s, 0).end())
  File "/usr/local/lib/python3.6/json/decoder.py", line 357, in raw_decode
    raise JSONDecodeError("Expecting value", s, err.value) from None
json.decoder.JSONDecodeError: Expecting value: line 1 column 1 (char 0)
[2021-06-27 17:32:28,062] {taskinstance.py:1481} ERROR - Task failed with exception
Traceback (most recent call last):
  File "/home/airflow/.local/lib/python3.6/site-packages/airflow/models/taskinstance.py", line 1137, in _run_raw_task
    self._prepare_and_execute_task_with_callbacks(context, task)
  File "/home/airflow/.local/lib/python3.6/site-packages/airflow/models/taskinstance.py", line 1311, in _prepare_and_execute_task_with_callbacks
    result = self._execute_task(context, task_copy)
  File "/home/airflow/.local/lib/python3.6/site-packages/airflow/models/taskinstance.py", line 1341, in _execute_task
    result = task_copy.execute(context=context)
  File "/home/airflow/.local/lib/python3.6/site-packages/airflow/operators/python.py", line 150, in execute
    return_value = self.execute_callable()
  File "/home/airflow/.local/lib/python3.6/site-packages/airflow/operators/python.py", line 161, in execute_callable
    return self.python_callable(*self.op_args, **self.op_kwargs)
  File "/opt/airflow/dags/example_mongo.py", line 15, in mysql_bulk_load_mongo
    conn.insert_one(mongo_collection = kwargs['table_name'], doc=data, mongo_db='test')
  File "/home/airflow/.local/lib/python3.6/site-packages/airflow/providers/mongo/hooks/mongo.py", line 160, in insert_one
    return collection.insert_one(doc, **kwargs)
  File "/home/airflow/.local/lib/python3.6/site-packages/pymongo/collection.py", line 701, in insert_one
    session=session),
  File "/home/airflow/.local/lib/python3.6/site-packages/pymongo/collection.py", line 615, in _insert
    bypass_doc_val, session)
  File "/home/airflow/.local/lib/python3.6/site-packages/pymongo/collection.py", line 603, in _insert_one
    acknowledged, _insert_command, session)
  File "/home/airflow/.local/lib/python3.6/site-packages/pymongo/mongo_client.py", line 1497, in _retryable_write
    with self._tmp_session(session) as s:
  File "/usr/local/lib/python3.6/contextlib.py", line 81, in __enter__
    return next(self.gen)
  File "/home/airflow/.local/lib/python3.6/site-packages/pymongo/mongo_client.py", line 1829, in _tmp_session
    s = self._ensure_session(session)
  File "/home/airflow/.local/lib/python3.6/site-packages/pymongo/mongo_client.py", line 1816, in _ensure_session
    return self.__start_session(True, causal_consistency=False)
  File "/home/airflow/.local/lib/python3.6/site-packages/pymongo/mongo_client.py", line 1766, in __start_session
    server_session = self._get_server_session()
  File "/home/airflow/.local/lib/python3.6/site-packages/pymongo/mongo_client.py", line 1802, in _get_server_session
    return self._topology.get_server_session()
  File "/home/airflow/.local/lib/python3.6/site-packages/pymongo/topology.py", line 499, in get_server_session
    None)
  File "/home/airflow/.local/lib/python3.6/site-packages/pymongo/topology.py", line 217, in _select_servers_loop
    (self._error_message(selector), timeout, self.description))
pymongo.errors.ServerSelectionTimeoutError: localhost:27017: [Errno 111] Connection refused, Timeout: 30s, Topology Description: <TopologyDescription id: 60d8b60dbfc5148378c9ae59, topology_type: Single, servers: [<ServerDescription ('localhost', 27017) server_type: Unknown, rtt: None, error=AutoReconnect('localhost:27017: [Errno 111] Connection refused',)>]>
[2021-06-27 17:32:28,067] {taskinstance.py:1531} INFO - Marking task as FAILED. dag_id=example_mongo, task_id=import_mysql_customer, execution_date=20210627T173156, start_date=20210627T173157, end_date=20210627T173228
[2021-06-27 17:32:28,102] {local_task_job.py:197} WARNING - State of this instance has been externally set to failed. Terminating instance.
[2021-06-27 17:32:28,112] {process_utils.py:100} INFO - Sending Signals.SIGTERM to GPID 5456
[2021-06-27 17:32:28,136] {process_utils.py:66} INFO - Process psutil.Process(pid=5456, status='terminated', exitcode=1, started='17:31:56') (5456) terminated with exit code 1
