[2021-06-27 06:49:49,750] {taskinstance.py:876} INFO - Dependencies all met for <TaskInstance: example_mysql.create_table_mysql_external_file 2021-06-27T06:49:43.622323+00:00 [queued]>
[2021-06-27 06:49:49,868] {taskinstance.py:876} INFO - Dependencies all met for <TaskInstance: example_mysql.create_table_mysql_external_file 2021-06-27T06:49:43.622323+00:00 [queued]>
[2021-06-27 06:49:49,869] {taskinstance.py:1067} INFO - 
--------------------------------------------------------------------------------
[2021-06-27 06:49:49,869] {taskinstance.py:1068} INFO - Starting attempt 1 of 1
[2021-06-27 06:49:49,877] {taskinstance.py:1069} INFO - 
--------------------------------------------------------------------------------
[2021-06-27 06:49:49,922] {taskinstance.py:1087} INFO - Executing <Task(MySqlOperator): create_table_mysql_external_file> on 2021-06-27T06:49:43.622323+00:00
[2021-06-27 06:49:49,947] {standard_task_runner.py:52} INFO - Started process 3823 to run task
[2021-06-27 06:49:49,969] {standard_task_runner.py:76} INFO - Running: ['***', 'tasks', 'run', 'example_mysql', 'create_table_mysql_external_file', '2021-06-27T06:49:43.622323+00:00', '--job-id', '28', '--pool', 'default_pool', '--raw', '--subdir', 'DAGS_FOLDER/example_mysql.py', '--cfg-path', '/tmp/tmpm4o5bnw0', '--error-file', '/tmp/tmplwfi_dri']
[2021-06-27 06:49:49,974] {standard_task_runner.py:77} INFO - Job 28: Subtask create_table_mysql_external_file
[2021-06-27 06:49:50,171] {logging_mixin.py:104} INFO - Running <TaskInstance: example_mysql.create_table_mysql_external_file 2021-06-27T06:49:43.622323+00:00 [running]> on host b69deda3a989
[2021-06-27 06:49:50,462] {taskinstance.py:1282} INFO - Exporting the following env vars:
AIRFLOW_CTX_DAG_OWNER=***
AIRFLOW_CTX_DAG_ID=example_mysql
AIRFLOW_CTX_TASK_ID=create_table_mysql_external_file
AIRFLOW_CTX_EXECUTION_DATE=2021-06-27T06:49:43.622323+00:00
AIRFLOW_CTX_DAG_RUN_ID=manual__2021-06-27T06:49:43.622323+00:00
[2021-06-27 06:49:50,476] {mysql.py:72} INFO - Executing: CREATE TABLE sys.Student (
    Id INTEGER NOT NULL,
    Name varchar(100) NULL
)
ENGINE=InnoDB
DEFAULT CHARSET=utf8mb4
COLLATE=utf8mb4_0900_ai_ci
COMMENT='Student';
[2021-06-27 06:49:50,530] {base.py:78} INFO - Using connection to: id: docker-mysql. Host: 192.168.1.27, Port: 3306, Schema: , Login: root, Password: ***, extra: {}
[2021-06-27 06:49:50,630] {dbapi.py:204} INFO - Running statement: CREATE TABLE sys.Student (
    Id INTEGER NOT NULL,
    Name varchar(100) NULL
)
ENGINE=InnoDB
DEFAULT CHARSET=utf8mb4
COLLATE=utf8mb4_0900_ai_ci
COMMENT='Student';, parameters: None
[2021-06-27 06:49:50,674] {taskinstance.py:1481} ERROR - Task failed with exception
Traceback (most recent call last):
  File "/home/airflow/.local/lib/python3.6/site-packages/airflow/models/taskinstance.py", line 1137, in _run_raw_task
    self._prepare_and_execute_task_with_callbacks(context, task)
  File "/home/airflow/.local/lib/python3.6/site-packages/airflow/models/taskinstance.py", line 1311, in _prepare_and_execute_task_with_callbacks
    result = self._execute_task(context, task_copy)
  File "/home/airflow/.local/lib/python3.6/site-packages/airflow/models/taskinstance.py", line 1341, in _execute_task
    result = task_copy.execute(context=context)
  File "/home/airflow/.local/lib/python3.6/site-packages/airflow/providers/mysql/operators/mysql.py", line 74, in execute
    hook.run(self.sql, autocommit=self.autocommit, parameters=self.parameters)
  File "/home/airflow/.local/lib/python3.6/site-packages/airflow/hooks/dbapi.py", line 184, in run
    self._run_command(cur, sql_statement, parameters)
  File "/home/airflow/.local/lib/python3.6/site-packages/airflow/hooks/dbapi.py", line 208, in _run_command
    cur.execute(sql_statement)
  File "/home/airflow/.local/lib/python3.6/site-packages/MySQLdb/cursors.py", line 206, in execute
    res = self._query(query)
  File "/home/airflow/.local/lib/python3.6/site-packages/MySQLdb/cursors.py", line 319, in _query
    db.query(q)
  File "/home/airflow/.local/lib/python3.6/site-packages/MySQLdb/connections.py", line 259, in query
    _mysql.connection.query(self, query)
MySQLdb._exceptions.OperationalError: (1050, "Table 'Student' already exists")
[2021-06-27 06:49:50,696] {taskinstance.py:1531} INFO - Marking task as FAILED. dag_id=example_mysql, task_id=create_table_mysql_external_file, execution_date=20210627T064943, start_date=20210627T064949, end_date=20210627T064950
[2021-06-27 06:49:50,799] {local_task_job.py:151} INFO - Task exited with return code 1
